Workbook

Sheet TQS FORM
B2: TGS> | D2: Assist > | G2: LOCATION - | N2: INSERT NAME
B7: Work Time | E7: WORKSITE START | G7: WORKSITE ENDED | I7: TGS - COMMENTS
B11: Week No | D11: PLANNED
B13: Day | I13: ADDITIONAL WORKS POST TAMPING
B15: Date | D15: ACTUAL
B17: Item No
B20: Track Details
E23: LXA | G23: WORKSITE MILEAGE FROM | I23: WORKSITE MILEAGE TO | K23: TPAT/GUPAT | M23: ELR / TRACK ID | O23: LINE | Q23: PLANNED START TAMP MILEAGE | S23: PLANNED END TAMP MILEAGE | U23: ACTUAL START TAMP MILEAGE | W23: ACTUAL END TAMP MILEAGE | Y23: LINE SPEED
C24: LEVEL CROSSINGS AFFECTED | AA24: SITE No
B25: 1 | E25: N/A | AA25: SITE 1
B27: 2 | E27: N/A
B29: 3 | E29: N/A | AA29: SITE 2
B31: 4 | E31: N/A
B33: 5 | E33: N/A | AA33: SITE 3
B35: 6 | E35: N/A
B37: 5 | E37: N/A | AA37: SITE 4
B39: 6 | E39: N/A
B42: OTM Details | G42: CHOOSE TRACK SECTION MANAGER
E45: DESIGN? YES / NO
B46: MACHINE TYPE | D46: HEAD CODE | G46: TOP/LINE | I46: PRE SD | K46: DESIGN SD | M46: POST SD | O46: MAX SLUE | Q46: MAX LIFT | S46: STONE USED | U46: TRACK CAT | W46: RAIL TEMP | Y46: S+C UNITS | AA46: SITE No
G48: TOP | AA48: SITE 1
G50: LINE
G52: TOP | AA52: SITE 2
G54: LINE
G56: TOP | AA56: SITE 3
G58: LINE
G60: TOP | AA60: SITE 4
G62: LINE
B65: PHOTOS:-
C69: PHOTO | N69: PHOTO
C102: PHOTO | N102: PHOTO

Sheet DIAGRAM

Sheet TRACE
A1: UP FAST
A60: UP FAST CONT..
A123: UP SLOW
A189: DOWN FAST
A246: DOWN FAST CONT..
A303: DOWN SLOW

Sheet CCQ CHART
A1: UP FAST
A50: UP SLOW
A99: DOWN FAST
A148: DOWN SLOW

Sheet TEF 3071 SITE 1
A1: OTM SITE CHECK and HANDBACK | Q1: TEF 3071 Issue 3 March 2026
B2: PART A
A4: LOCATION DETAIL
A5: Location | F5: ='TQS FORM'!N2 -> INSERT NAME | M5: ELR | P5: ='TQS FORM'!M25 -> 0 | T5: Line(s) | Z5: ='TQS FORM'!O25 -> 0 | AF5: Track ID(s) | AL5: ='TQS FORM'!M27 -> 0
A6: Mileage From | F6: ='TQS FORM'!U25 -> 0 | U6: Mileage To | AC6: ='TQS FORM'!W25 -> 0
A7: Published speed (PSR) | F7: ='TQS FORM'!Y25 -> 0 | K7: Site protected by ESR/TSR? | R7: NO | AC7: If yes, what speed? | AL7: mph
A8: Planned opening line speed | F8: ='TQS FORM'!Y25 -> 0 | K8: Note: if planned opening speed is higher than existing PSR/TSR/ESR, TEF3203 is also to be completed by an Authorised Person (see NR/L2/TRK/001/mod13)
A9: WORK TYPE
A10: The type of work carried out determines which part of this TEF requires to be completed
A11: Work undertaken | Y11: Y/N | AD11: Part to be completed
A12: o Plain line tamping; measurement and compensation method | Y12: NO | AD12: Part B
A13: o Plain line tamping; applying a design | Y13: YES | AD13: Part B
A14: o Plain line tamping; absolute track geometry (ATG) location | Y14: NO | AD14: LNW ATG forms to be used
A15: o DTS | Y15: NO | AD15: Part B
A16: o S&C tamping; single machine | Y16: NO | AD16: Part B (for each affected TID)
A17: o S&C tamping; multiple machines | Y17: NO | AD17: Part B (for each affected TID)
A18: o Plain line stoneblowing | Y18: NO | AD18: Part B
A19: o S&C stoneblowing with multi-purpose stoneblower | Y19: NO | AD19: Part C (for each affected TID)
A20: SIGN OFF
A21: Part | C21: B | F21: completed by (name): | O21: ='TQS FORM'!C2 -> 0
A22: Date of inspection: | H22: ='TQS FORM'!C15 -> 0 | O22: Time of inspection: | Y22: ='TQS FORM'!G15 -> 0
A23: Following inspection of the track and a review of the post-work recording run data, I can confirm that:
A24: o track geometry (twist, top, line and gauge) is in accordance with ATG requirements / installation tolerances / maintenance tolerances.
A25: o structural and passing clearances have not been affected / have been checked and are within tolerance .
A26: o the track is safe to re-open for trains at | O26: ='TQS FORM'!Y25 -> 0 | R26: # delete as required
A27: For ATG routes | E27: Tamping Leader (name) | W27: Signed | AJ27: Date
E28: TGS (name) | W28: Signed | AJ28: Date
A29: All other routes | E29: TGS (name) | M29: ='TQS FORM'!C2 -> 0 | W29: Signed | AB29: ='TQS FORM'!C2 -> 0 | AJ29: Date | AM29: ='TQS FORM'!C15 -> 0
A30: ADDITIONAL WORKS
A31: The following additional work is required: (Include a timescale for completion where appropriate) | L31: ='TQS FORM'!I14 -> 0
A32: I have reviewed the proposed follow-up work and taken the necessary actions. Work entered into ellipse? Circle or delete as appropiate | AE32: YES | AL32: NO
A33: Name of SM[T]: | O33: Signed: | AH33: Date:
A34: PART B: Tamper or DTS (plain line or S&C) or Stoneblower (plain line)
A36: PRE-WORK SITE RECORD
A37: Pre work site record
A38: Maximum recorded 35m vertical SD value | N38: ='TQS FORM'!I48 -> 0 | T38: Maximum recorded 35m lateral SD value | AL38: ='TQS FORM'!I50 -> 0
A40: WORK-IN-PROGRESS CHECKS
A41: Checks are particularly critical o in the first 40-50 yards (to confirm OTM working correctly) o at run-in and run-out locations o adjacent to, on or under structures
A42: Location $ | G42: Design cant | L42: Actual cant | Q42: Error [+/-] | Y42: Vertical datum [+/-] | AE42: Structure clearance | AK42: Passing clearance
A43: Ramp in
...

Sheet TEF3207 SITE 1
A1: Record of Site Details for Critical Rail Temperature Calculation (to apply the requirements of NR/L2/TRK/001/mod14) | L1: TEF 3207 issue 4
L2: July 2021
C3: Disturbed | J3: (delete as required) | M3: Date: | N3: ='TQS FORM'!C15 -> 0
B4: If disturbed, describe work undertaken: | E4: ='TQS FORM'!B48 -> 0 | M4: Site rail temperature: | O4: ='TQS FORM'!W48 -> 0 | P4: ºC
B5: (Tamp, stoneblow, manual correction to top & line, change sleepers/bearers, dig wetbeds, ballast regulation, etc.)
B7: Site location details | E7: ='TQS FORM'!N2 -> INSERT NAME | M7: ='TQS FORM'!G42 -> CHOOSE TRACK SECTION MANAGER
B8: Location Name: | K8: SM[T] area:
D9: ELR: | E9: ='TQS FORM'!M25 -> 0 | F9: LINE | G9: ='TQS FORM'!M27 -> 0 | H9: Line: | I9: ='TQS FORM'!O25 -> 0 | M9: Point No(s): | O9: ='TQS FORM'!Y48 -> 0
E10: Mileage From: | F10: ='TQS FORM'!U25 -> 0 | K10: To: | L10: ='TQS FORM'!W25 -> 0
B13: Track type - Tick the appropriate box (boxes) | L13: Rail type - Tick the appropriate box (boxes)
B14: PL-CWR | E14: S&C | F14: a | G14: RT60/NR60 S&C | M14: BH | O14: FB | P14: a
B16: PL-Jointed | E16: Rails in excess of 30m (on curve) | I16: Adj. switch | O16: CEN60
B18: Sleeper/bearer type - Tick the appropriate box (boxes)
B19: Concrete | D19: a | E19: G44 | G19: Wood | I19: Steel | L19: Composite
B21: Number of sleepers/bearers per 60ft (18m) - Tick the appropriate box - one box only
C22: 24-25 | E22: 26-27 | F22: a | G22: 28-29 | I22: 30+
B24: Track Curvature - Tick the appropriate box - one box only | L24: Lateral Resistance Plates - Tick one box only
D25: Radius 350m or less | M25: No LRPs | P25: a
D26: Radius between 351m and 500m | M26: LRPs fitted and effective
D27: Radius between 501m and 800m | M27: LRPs unfastened/loosened
D28: Radius between 801m and 1500m
D29: Radius greater than 1500m (up to and including straight track) | I29: a | M29: Ballast type - Tick one box only
D30: Curve transition | M30: non-Granite (Ash etc)
D31: Radius unknown | M31: Stone ballast | P31: a
A34: Track condition / work activity - Tick the appropriate box (boxes)
C35: FOR CWR ONLY | H35: TICK | K35: FOR JOINTED TRACK ONLY | P35: TICK
C36: 1 | D36: Undisturbed, fully ballasted and consolidated | K36: 1 | L36: Undisturbed, fully ballasted and consolidated
C37: 2 | D37: Re-railed only (no other disturbance or deficiency) | K37: 2 | L37: Re-railed only (no other disturbance or deficiency)
B38: Disturbance | C38: 3 | D38: Tamped/lined with slues/lifts up to 25mm | H38: a | J38: Disturbance | K38: 3 | L38: Tamped/Lined with slues/lifts up to 25mm
C39: 4 | D39: Tamped/lined with slues/lifts > 25mm | K39: 4 | L39: Tamped/Lined with slues/lifts > 25mm
C40: 5 | D40: Mechanised stoneblown | K40: 5 | L40: Mechanised stoneblown
C41: 6 | D41: Tamped or stoneblown S&C | K41: 6 | L41: Manual correction to top and line (MSP, Lift & pack, Kango, orbital tamper, hand-held stoneblown etc.)
C42: 7 | D42: Manual correction to top and line (MSP, Lift & pack, Kango, orbital tamper, hand-held stoneblown etc.) Less than 8 beds | K42: 7 | L42: Ballast disturbance beyond sleeper end only with fully consolidated ballast, ballast profile fully restored
C43: 8 | D43: Manual correction to top and line (MSP, Lift & pack, Kango, orbital tamper, hand-held stoneblown etc.) 8 beds or more | K43: 8 | L43: Ballast generally full between sleepers and on shoulders, but not consolidated (less than 8 beds)
C44: 9 | D44: Ballast disturbance beyond sleeper end only (up to 3 beds) with fully consolidated ballast under the sleepers, ballast profile fully restored | K44: 9 | L44: Ballast generally full between sleepers and on shoulders, but not consolidated (8 beds or more)
C45: 10 | D45: Ballast disturbance beyond sleeper end only (more than 3 beds) with fully consolidated ballast under the sleepers, ballast profile fully restored | J45: Deficiency | K45: 10 | L45: Severe shortage of ballast between sleepers, extending 8 beds or more
C46: 11 | D46: Ballast generally full between sleepers and on shoulders, but not consolidated (less than 8 beds) | K46: 11 | L46: Severe shortage of ballast at sleeper ends, extending 3 beds or more.
C47: 12 | D47: Ballast generally full between sleepers and on shoulders, but not consolidated (8 beds or more) | K47: 12 | L47: Severe shortage of ballast between sleepers and at sleeper ends, extending 8 beds or more
B48: Deficiency | C48: 13 | D48: No ballast shoulder: level with sleeper top (no other disturbance or deficiency) | K48: 13 | L48: 3 or more consecutive sleepers voided at 15mm or more or
C49: 14 | D49: Severe shortage of ballast between sleepers, extending 8 or more consecutive beds | L49: 3 or more consecutive slurried beds, where ballast is not compacted against the sleeper sides/ends
...

Sheet TEF 3071 SITE 2
A1: OTM SITE CHECK and HANDBACK | Q1: TEF 3071 Issue 3 March 2026
B2: PART A
A4: LOCATION DETAIL
A5: Location | F5: ='TQS FORM'!N2 -> INSERT NAME | M5: ELR | P5: ='TQS FORM'!M29 -> 0 | T5: Line(s) | Z5: ='TQS FORM'!O29 -> 0 | AF5: Track ID(s) | AL5: ='TQS FORM'!M31 -> 0
A6: Mileage From | F6: ='TQS FORM'!U29 -> 0 | U6: Mileage To | AC6: ='TQS FORM'!W29 -> 0
A7: Published speed (PSR) | F7: ='TQS FORM'!Y29 -> 0 | K7: Site protected by ESR/TSR? | R7: NO | AC7: If yes, what speed? | AL7: mph
A8: Planned opening line speed | F8: =F7 -> 0 | K8: Note: if planned opening speed is higher than existing PSR/TSR/ESR, TEF3203 is also to be completed by an Authorised Person (see NR/L2/TRK/001/mod13)
A9: WORK TYPE
A10: The type of work carried out determines which part of this TEF requires to be completed
A11: Work undertaken | Y11: Y/N | AD11: Part to be completed
A12: o Plain line tamping; measurement and compensation method | Y12: NO | AD12: Part B
A13: o Plain line tamping; applying a design | Y13: YES | AD13: Part B
A14: o Plain line tamping; absolute track geometry (ATG) location | Y14: NO | AD14: LNW ATG forms to be used
A15: o DTS | Y15: NO | AD15: Part B
A16: o S&C tamping; single machine | Y16: NO | AD16: Part B (for each affected TID)
A17: o S&C tamping; multiple machines | Y17: NO | AD17: Part B (for each affected TID)
A18: o Plain line stoneblowing | Y18: NO | AD18: Part B
A19: o S&C stoneblowing with multi-purpose stoneblower | Y19: NO | AD19: Part C (for each affected TID)
A20: SIGN OFF
A21: Part | C21: B | F21: completed by (name): | O21: ='TQS FORM'!C2 -> 0
A22: Date of inspection: | H22: ='TQS FORM'!C15 -> 0 | O22: Time of inspection: | Y22: ='TQS FORM'!G15 -> 0
A23: Following inspection of the track and a review of the post-work recording run data, I can confirm that:
A24: o track geometry (twist, top, line and gauge) is in accordance with ATG requirements / installation tolerances / maintenance tolerances.
A25: o structural and passing clearances have not been affected / have been checked and are within tolerance .
A26: o the track is safe to re-open for trains at | O26: =F7 -> 0 | R26: # delete as required
A27: For ATG routes | E27: Tamping Leader (name) | W27: Signed | AJ27: Date
E28: TGS (name) | W28: Signed | AJ28: Date
A29: All other routes | E29: TGS (name) | M29: ='TQS FORM'!C2 -> 0 | W29: Signed | AB29: ='TQS FORM'!C2 -> 0 | AJ29: Date | AM29: ='TQS FORM'!C15 -> 0
A30: ADDITIONAL WORKS
A31: The following additional work is required: (Include a timescale for completion where appropriate) | L31: ='TQS FORM'!I14 -> 0
A32: I have reviewed the proposed follow-up work and taken the necessary actions. Work entered into ellipse? Circle or delete as appropiate | AE32: YES | AL32: NO
A33: Name of SM[T]: | O33: Signed: | AH33: Date:
A34: PART B: Tamper or DTS (plain line or S&C) or Stoneblower (plain line)
A36: PRE-WORK SITE RECORD
A37: Pre work site record
A38: Maximum recorded 35m vertical SD value | N38: ='TQS FORM'!I52 -> 0 | T38: Maximum recorded 35m lateral SD value | AL38: ='TQS FORM'!I54 -> 0
A40: WORK-IN-PROGRESS CHECKS
A41: Checks are particularly critical o in the first 40-50 yards (to confirm OTM working correctly) o at run-in and run-out locations o adjacent to, on or under structures
A42: Location $ | G42: Design cant | L42: Actual cant | Q42: Error [+/-] | Y42: Vertical datum [+/-] | AE42: Structure clearance | AK42: Passing clearance
A43: Ramp in
...

Sheet TEF3207 SITE 2
A1: Record of Site Details for Critical Rail Temperature Calculation (to apply the requirements of NR/L2/TRK/001/mod14) | L1: TEF 3207 issue 4
L2: July 2021
C3: Disturbed | J3: (delete as required) | M3: Date: | N3: ='TQS FORM'!C15 -> 0
B4: If disturbed, describe work undertaken: | E4: ='TQS FORM'!B48 -> 0 | M4: Site rail temperature: | O4: ='TQS FORM'!W52 -> 0 | P4: ºC
B5: (Tamp, stoneblow, manual correction to top & line, change sleepers/bearers, dig wetbeds, ballast regulation, etc.)
B7: Site location details | E7: ='TQS FORM'!N2 -> INSERT NAME | M7: ='TQS FORM'!G42 -> CHOOSE TRACK SECTION MANAGER
B8: Location Name: | K8: SM[T] area:
D9: ELR: | E9: ='TQS FORM'!M29 -> 0 | F9: LINE | G9: ='TQS FORM'!M31 -> 0 | H9: Line: | I9: ='TQS FORM'!O29 -> 0 | M9: Point No(s): | O9: ='TQS FORM'!Y52 -> 0
E10: Mileage From: | F10: ='TQS FORM'!U29 -> 0 | K10: To: | L10: ='TQS FORM'!W29 -> 0
B13: Track type - Tick the appropriate box (boxes) | L13: Rail type - Tick the appropriate box (boxes)
B14: PL-CWR | E14: S&C | F14: a | G14: RT60/NR60 S&C | M14: BH | O14: FB | P14: a
B16: PL-Jointed | E16: Rails in excess of 30m (on curve) | I16: Adj. switch | O16: CEN60
B18: Sleeper/bearer type - Tick the appropriate box (boxes)
B19: Concrete | D19: a | E19: G44 | G19: Wood | I19: Steel | L19: Composite
B21: Number of sleepers/bearers per 60ft (18m) - Tick the appropriate box - one box only
C22: 24-25 | E22: 26-27 | F22: a | G22: 28-29 | I22: 30+
B24: Track Curvature - Tick the appropriate box - one box only | L24: Lateral Resistance Plates - Tick one box only
D25: Radius 350m or less | M25: No LRPs | P25: a
D26: Radius between 351m and 500m | M26: LRPs fitted and effective
D27: Radius between 501m and 800m | M27: LRPs unfastened/loosened
D28: Radius between 801m and 1500m
D29: Radius greater than 1500m (up to and including straight track) | I29: a | M29: Ballast type - Tick one box only
D30: Curve transition | M30: non-Granite (Ash etc)
D31: Radius unknown | M31: Stone ballast | P31: a
A34: Track condition / work activity - Tick the appropriate box (boxes)
C35: FOR CWR ONLY | H35: TICK | K35: FOR JOINTED TRACK ONLY | P35: TICK
C36: 1 | D36: Undisturbed, fully ballasted and consolidated | K36: 1 | L36: Undisturbed, fully ballasted and consolidated
C37: 2 | D37: Re-railed only (no other disturbance or deficiency) | K37: 2 | L37: Re-railed only (no other disturbance or deficiency)
B38: Disturbance | C38: 3 | D38: Tamped/lined with slues/lifts up to 25mm | H38: a | J38: Disturbance | K38: 3 | L38: Tamped/Lined with slues/lifts up to 25mm
C39: 4 | D39: Tamped/lined with slues/lifts > 25mm | K39: 4 | L39: Tamped/Lined with slues/lifts > 25mm
C40: 5 | D40: Mechanised stoneblown | K40: 5 | L40: Mechanised stoneblown
C41: 6 | D41: Tamped or stoneblown S&C | K41: 6 | L41: Manual correction to top and line (MSP, Lift & pack, Kango, orbital tamper, hand-held stoneblown etc.)
C42: 7 | D42: Manual correction to top and line (MSP, Lift & pack, Kango, orbital tamper, hand-held stoneblown etc.) Less than 8 beds | K42: 7 | L42: Ballast disturbance beyond sleeper end only with fully consolidated ballast, ballast profile fully restored
C43: 8 | D43: Manual correction to top and line (MSP, Lift & pack, Kango, orbital tamper, hand-held stoneblown etc.) 8 beds or more | K43: 8 | L43: Ballast generally full between sleepers and on shoulders, but not consolidated (less than 8 beds)
C44: 9 | D44: Ballast disturbance beyond sleeper end only (up to 3 beds) with fully consolidated ballast under the sleepers, ballast profile fully restored | K44: 9 | L44: Ballast generally full between sleepers and on shoulders, but not consolidated (8 beds or more)
C45: 10 | D45: Ballast disturbance beyond sleeper end only (more than 3 beds) with fully consolidated ballast under the sleepers, ballast profile fully restored | J45: Deficiency | K45: 10 | L45: Severe shortage of ballast between sleepers, extending 8 beds or more
C46: 11 | D46: Ballast generally full between sleepers and on shoulders, but not consolidated (less than 8 beds) | K46: 11 | L46: Severe shortage of ballast at sleeper ends, extending 3 beds or more.
C47: 12 | D47: Ballast generally full between sleepers and on shoulders, but not consolidated (8 beds or more) | K47: 12 | L47: Severe shortage of ballast between sleepers and at sleeper ends, extending 8 beds or more
B48: Deficiency | C48: 13 | D48: No ballast shoulder: level with sleeper top (no other disturbance or deficiency) | K48: 13 | L48: 3 or more consecutive sleepers voided at 15mm or more or
C49: 14 | D49: Severe shortage of ballast between sleepers, extending 8 or more consecutive beds | L49: 3 or more consecutive slurried beds, where ballast is not compacted against the sleeper sides/ends
...

Sheet TEF 3071 SITE 3
A1: OTM SITE CHECK and HANDBACK | Q1: TEF 3071 Issue 3 March 2026
B2: PART A
A4: LOCATION DETAIL
A5: Location | F5: ='TQS FORM'!N2 -> INSERT NAME | M5: ELR | P5: ='TQS FORM'!M33 -> 0 | T5: Line(s) | Z5: ='TQS FORM'!O33 -> 0 | AF5: Track ID(s) | AL5: ='TQS FORM'!M35 -> 0
A6: Mileage From | F6: ='TQS FORM'!U33 -> 0 | U6: Mileage To | AC6: ='TQS FORM'!W33 -> 0
A7: Published speed (PSR) | F7: ='TQS FORM'!Y33 -> 0 | K7: Site protected by ESR/TSR? | R7: NO | AC7: If yes, what speed? | AL7: mph
A8: Planned opening line speed | F8: ='TQS FORM'!Y33 -> 0 | K8: Note: if planned opening speed is higher than existing PSR/TSR/ESR, TEF3203 is also to be completed by an Authorised Person (see NR/L2/TRK/001/mod13)
A9: WORK TYPE
A10: The type of work carried out determines which part of this TEF requires to be completed
A11: Work undertaken | Y11: Y/N | AD11: Part to be completed
A12: o Plain line tamping; measurement and compensation method | Y12: NO | AD12: Part B
A13: o Plain line tamping; applying a design | Y13: YES | AD13: Part B
A14: o Plain line tamping; absolute track geometry (ATG) location | Y14: NO | AD14: LNW ATG forms to be used
A15: o DTS | Y15: NO | AD15: Part B
A16: o S&C tamping; single machine | Y16: NO | AD16: Part B (for each affected TID)
A17: o S&C tamping; multiple machines | Y17: NO | AD17: Part B (for each affected TID)
A18: o Plain line stoneblowing | Y18: NO | AD18: Part B
A19: o S&C stoneblowing with multi-purpose stoneblower | Y19: NO | AD19: Part C (for each affected TID)
A20: SIGN OFF
A21: Part | C21: B | F21: completed by (name): | O21: ='TQS FORM'!C2 -> 0
A22: Date of inspection: | H22: ='TQS FORM'!C15 -> 0 | O22: Time of inspection: | Y22: ='TQS FORM'!G15 -> 0
A23: Following inspection of the track and a review of the post-work recording run data, I can confirm that:
A24: o track geometry (twist, top, line and gauge) is in accordance with ATG requirements / installation tolerances / maintenance tolerances.
A25: o structural and passing clearances have not been affected / have been checked and are within tolerance .
A26: o the track is safe to re-open for trains at | O26: =F7 -> 0 | R26: # delete as required
A27: For ATG routes | E27: Tamping Leader (name) | W27: Signed | AJ27: Date
E28: TGS (name) | W28: Signed | AJ28: Date
A29: All other routes | E29: TGS (name) | M29: ='TQS FORM'!C2 -> 0 | W29: Signed | AB29: ='TQS FORM'!C2 -> 0 | AJ29: Date | AM29: ='TQS FORM'!C15 -> 0
A30: ADDITIONAL WORKS
A31: The following additional work is required: (Include a timescale for completion where appropriate) | L31: ='TQS FORM'!I14 -> 0
A32: I have reviewed the proposed follow-up work and taken the necessary actions. Work entered into ellipse? Circle or delete as appropiate | AE32: YES | AL32: NO
A33: Name of SM[T]: | O33: Signed: | AH33: Date:
A34: PART B: Tamper or DTS (plain line or S&C) or Stoneblower (plain line)
A36: PRE-WORK SITE RECORD
A37: Pre work site record
A38: Maximum recorded 35m vertical SD value | N38: ='TQS FORM'!I56 -> 0 | T38: Maximum recorded 35m lateral SD value | AL38: ='TQS FORM'!I58 -> 0
A40: WORK-IN-PROGRESS CHECKS
A41: Checks are particularly critical o in the first 40-50 yards (to confirm OTM working correctly) o at run-in and run-out locations o adjacent to, on or under structures
A42: Location $ | G42: Design cant | L42: Actual cant | Q42: Error [+/-] | Y42: Vertical datum [+/-] | AE42: Structure clearance | AK42: Passing clearance
A43: Ramp in
...

Sheet TEF3207 SITE 3
A1: Record of Site Details for Critical Rail Temperature Calculation (to apply the requirements of NR/L2/TRK/001/mod14) | L1: TEF 3207 issue 4
L2: July 2021
C3: Disturbed | J3: (delete as required) | M3: Date: | N3: ='TQS FORM'!C15 -> 0
B4: If disturbed, describe work undertaken: | E4: ='TQS FORM'!B48 -> 0 | M4: Site rail temperature: | O4: ='TQS FORM'!W56 -> 0 | P4: ºC
B5: (Tamp, stoneblow, manual correction to top & line, change sleepers/bearers, dig wetbeds, ballast regulation, etc.)
B7: Site location details | E7: ='TQS FORM'!N2 -> INSERT NAME | M7: ='TQS FORM'!G42 -> CHOOSE TRACK SECTION MANAGER
B8: Location Name: | K8: SM[T] area:
D9: ELR: | E9: ='TQS FORM'!M33 -> 0 | F9: LINE | G9: ='TQS FORM'!M35 -> 0 | H9: Line: | I9: ='TQS FORM'!O33 -> 0 | M9: Point No(s): | O9: ='TQS FORM'!Y56 -> 0
E10: Mileage From: | F10: ='TQS FORM'!U33 -> 0 | K10: To: | L10: ='TQS FORM'!W33 -> 0
B13: Track type - Tick the appropriate box (boxes) | L13: Rail type - Tick the appropriate box (boxes)
B14: PL-CWR | E14: S&C | F14: a | G14: RT60/NR60 S&C | M14: BH | O14: FB | P14: a
B16: PL-Jointed | E16: Rails in excess of 30m (on curve) | I16: Adj. switch | O16: CEN60
B18: Sleeper/bearer type - Tick the appropriate box (boxes)
B19: Concrete | D19: a | E19: G44 | G19: Wood | I19: Steel | L19: Composite
B21: Number of sleepers/bearers per 60ft (18m) - Tick the appropriate box - one box only
C22: 24-25 | E22: 26-27 | F22: a | G22: 28-29 | I22: 30+
B24: Track Curvature - Tick the appropriate box - one box only | L24: Lateral Resistance Plates - Tick one box only
D25: Radius 350m or less | M25: No LRPs | P25: a
D26: Radius between 351m and 500m | M26: LRPs fitted and effective
D27: Radius between 501m and 800m | M27: LRPs unfastened/loosened
D28: Radius between 801m and 1500m
D29: Radius greater than 1500m (up to and including straight track) | I29: a | M29: Ballast type - Tick one box only
D30: Curve transition | M30: non-Granite (Ash etc)
D31: Radius unknown | M31: Stone ballast | P31: a
A34: Track condition / work activity - Tick the appropriate box (boxes)
C35: FOR CWR ONLY | H35: TICK | K35: FOR JOINTED TRACK ONLY | P35: TICK
C36: 1 | D36: Undisturbed, fully ballasted and consolidated | K36: 1 | L36: Undisturbed, fully ballasted and consolidated
C37: 2 | D37: Re-railed only (no other disturbance or deficiency) | K37: 2 | L37: Re-railed only (no other disturbance or deficiency)
B38: Disturbance | C38: 3 | D38: Tamped/lined with slues/lifts up to 25mm | H38: a | J38: Disturbance | K38: 3 | L38: Tamped/Lined with slues/lifts up to 25mm
C39: 4 | D39: Tamped/lined with slues/lifts > 25mm | K39: 4 | L39: Tamped/Lined with slues/lifts > 25mm
C40: 5 | D40: Mechanised stoneblown | K40: 5 | L40: Mechanised stoneblown
C41: 6 | D41: Tamped or stoneblown S&C | K41: 6 | L41: Manual correction to top and line (MSP, Lift & pack, Kango, orbital tamper, hand-held stoneblown etc.)
C42: 7 | D42: Manual correction to top and line (MSP, Lift & pack, Kango, orbital tamper, hand-held stoneblown etc.) Less than 8 beds | K42: 7 | L42: Ballast disturbance beyond sleeper end only with fully consolidated ballast, ballast profile fully restored
C43: 8 | D43: Manual correction to top and line (MSP, Lift & pack, Kango, orbital tamper, hand-held stoneblown etc.) 8 beds or more | K43: 8 | L43: Ballast generally full between sleepers and on shoulders, but not consolidated (less than 8 beds)
C44: 9 | D44: Ballast disturbance beyond sleeper end only (up to 3 beds) with fully consolidated ballast under the sleepers, ballast profile fully restored | K44: 9 | L44: Ballast generally full between sleepers and on shoulders, but not consolidated (8 beds or more)
C45: 10 | D45: Ballast disturbance beyond sleeper end only (more than 3 beds) with fully consolidated ballast under the sleepers, ballast profile fully restored | J45: Deficiency | K45: 10 | L45: Severe shortage of ballast between sleepers, extending 8 beds or more
C46: 11 | D46: Ballast generally full between sleepers and on shoulders, but not consolidated (less than 8 beds) | K46: 11 | L46: Severe shortage of ballast at sleeper ends, extending 3 beds or more.
C47: 12 | D47: Ballast generally full between sleepers and on shoulders, but not consolidated (8 beds or more) | K47: 12 | L47: Severe shortage of ballast between sleepers and at sleeper ends, extending 8 beds or more
B48: Deficiency | C48: 13 | D48: No ballast shoulder: level with sleeper top (no other disturbance or deficiency) | K48: 13 | L48: 3 or more consecutive sleepers voided at 15mm or more or
C49: 14 | D49: Severe shortage of ballast between sleepers, extending 8 or more consecutive beds | L49: 3 or more consecutive slurried beds, where ballast is not compacted against the sleeper sides/ends
...

Sheet TEF 3071 SITE 4
A1: OTM SITE CHECK and HANDBACK | Q1: TEF 3071 Issue 3 March 2026
B2: PART A
A4: LOCATION DETAIL
A5: Location | F5: ='TQS FORM'!N2 -> INSERT NAME | M5: ELR | P5: ='TQS FORM'!M25 -> 0 | T5: Line(s) | Z5: ='TQS FORM'!O37 -> 0 | AF5: Track ID(s) | AL5: ='TQS FORM'!M39 -> 0
A6: Mileage From | F6: ='TQS FORM'!U37 -> 0 | U6: Mileage To | AC6: ='TQS FORM'!W37 -> 0
A7: Published speed (PSR) | F7: ='TQS FORM'!Y37 -> 0 | K7: Site protected by ESR/TSR? | R7: NO | AC7: If yes, what speed? | AL7: mph
A8: Planned opening line speed | F8: ='TQS FORM'!Y37 -> 0 | K8: Note: if planned opening speed is higher than existing PSR/TSR/ESR, TEF3203 is also to be completed by an Authorised Person (see NR/L2/TRK/001/mod13)
A9: WORK TYPE
A10: The type of work carried out determines which part of this TEF requires to be completed
A11: Work undertaken | Y11: Y/N | AD11: Part to be completed
A12: o Plain line tamping; measurement and compensation method | Y12: NO | AD12: Part B
A13: o Plain line tamping; applying a design | Y13: YES | AD13: Part B
A14: o Plain line tamping; absolute track geometry (ATG) location | Y14: NO | AD14: LNW ATG forms to be used
A15: o DTS | Y15: NO | AD15: Part B
A16: o S&C tamping; single machine | Y16: NO | AD16: Part B (for each affected TID)
A17: o S&C tamping; multiple machines | Y17: NO | AD17: Part B (for each affected TID)
A18: o Plain line stoneblowing | Y18: NO | AD18: Part B
A19: o S&C stoneblowing with multi-purpose stoneblower | Y19: NO | AD19: Part C (for each affected TID)
A20: SIGN OFF
A21: Part | C21: B | F21: completed by (name): | O21: ='TQS FORM'!C2 -> 0
A22: Date of inspection: | H22: ='TQS FORM'!C15 -> 0 | O22: Time of inspection: | Y22: ='TQS FORM'!G15 -> 0
A23: Following inspection of the track and a review of the post-work recording run data, I can confirm that:
A24: o track geometry (twist, top, line and gauge) is in accordance with ATG requirements / installation tolerances / maintenance tolerances.
A25: o structural and passing clearances have not been affected / have been checked and are within tolerance .
A26: o the track is safe to re-open for trains at | O26: =F7 -> 0 | R26: # delete as required
A27: For ATG routes | E27: Tamping Leader (name) | W27: Signed | AJ27: Date
E28: TGS (name) | W28: Signed | AJ28: Date
A29: All other routes | E29: TGS (name) | M29: ='TQS FORM'!C2 -> 0 | W29: Signed | AB29: ='TQS FORM'!C2 -> 0 | AJ29: Date | AM29: ='TQS FORM'!C15 -> 0
A30: ADDITIONAL WORKS
A31: The following additional work is required: (Include a timescale for completion where appropriate) | L31: ='TQS FORM'!I14 -> 0
A32: I have reviewed the proposed follow-up work and taken the necessary actions. Work entered into ellipse? Circle or delete as appropiate | AE32: YES | AL32: NO
A33: Name of SM[T]: | O33: Signed: | AH33: Date:
A34: PART B: Tamper or DTS (plain line or S&C) or Stoneblower (plain line)
A36: PRE-WORK SITE RECORD
A37: Pre work site record
A38: Maximum recorded 35m vertical SD value | N38: ='TQS FORM'!I60 -> 0 | T38: Maximum recorded 35m lateral SD value | AL38: ='TQS FORM'!I62 -> 0
A40: WORK-IN-PROGRESS CHECKS
A41: Checks are particularly critical o in the first 40-50 yards (to confirm OTM working correctly) o at run-in and run-out locations o adjacent to, on or under structures
A42: Location $ | G42: Design cant | L42: Actual cant | Q42: Error [+/-] | Y42: Vertical datum [+/-] | AE42: Structure clearance | AK42: Passing clearance
A43: Ramp in
...

Sheet TEF3207 SITE 4
A1: Record of Site Details for Critical Rail Temperature Calculation (to apply the requirements of NR/L2/TRK/001/mod14) | L1: TEF 3207 issue 4
L2: July 2021
C3: Disturbed | J3: (delete as required) | M3: Date: | N3: ='TQS FORM'!C15 -> 0
B4: If disturbed, describe work undertaken: | E4: ='TQS FORM'!B48 -> 0 | M4: Site rail temperature: | O4: ='TQS FORM'!W60 -> 0 | P4: ºC
B5: (Tamp, stoneblow, manual correction to top & line, change sleepers/bearers, dig wetbeds, ballast regulation, etc.)
B7: Site location details | E7: ='TQS FORM'!N2 -> INSERT NAME | M7: ='TQS FORM'!G42 -> CHOOSE TRACK SECTION MANAGER
B8: Location Name: | K8: SM[T] area:
D9: ELR: | E9: ='TQS FORM'!M37 -> 0 | F9: LINE | G9: ='TQS FORM'!M39 -> 0 | H9: Line: | I9: ='TQS FORM'!O37 -> 0 | M9: Point No(s): | O9: ='TQS FORM'!Y60 -> 0
E10: Mileage From: | F10: ='TQS FORM'!U37 -> 0 | K10: To: | L10: ='TQS FORM'!W37 -> 0
B13: Track type - Tick the appropriate box (boxes) | L13: Rail type - Tick the appropriate box (boxes)
B14: PL-CWR | E14: S&C | F14: a | G14: RT60/NR60 S&C | M14: BH | O14: FB | P14: a
B16: PL-Jointed | E16: Rails in excess of 30m (on curve) | I16: Adj. switch | O16: CEN60
B18: Sleeper/bearer type - Tick the appropriate box (boxes)
B19: Concrete | D19: a | E19: G44 | G19: Wood | I19: Steel | L19: Composite
B21: Number of sleepers/bearers per 60ft (18m) - Tick the appropriate box - one box only
C22: 24-25 | E22: 26-27 | F22: a | G22: 28-29 | I22: 30+
B24: Track Curvature - Tick the appropriate box - one box only | L24: Lateral Resistance Plates - Tick one box only
D25: Radius 350m or less | M25: No LRPs | P25: a
D26: Radius between 351m and 500m | M26: LRPs fitted and effective
D27: Radius between 501m and 800m | M27: LRPs unfastened/loosened
D28: Radius between 801m and 1500m
D29: Radius greater than 1500m (up to and including straight track) | I29: a | M29: Ballast type - Tick one box only
D30: Curve transition | M30: non-Granite (Ash etc)
D31: Radius unknown | M31: Stone ballast | P31: a
A34: Track condition / work activity - Tick the appropriate box (boxes)
C35: FOR CWR ONLY | H35: TICK | K35: FOR JOINTED TRACK ONLY | P35: TICK
C36: 1 | D36: Undisturbed, fully ballasted and consolidated | K36: 1 | L36: Undisturbed, fully ballasted and consolidated
C37: 2 | D37: Re-railed only (no other disturbance or deficiency) | K37: 2 | L37: Re-railed only (no other disturbance or deficiency)
B38: Disturbance | C38: 3 | D38: Tamped/lined with slues/lifts up to 25mm | H38: a | J38: Disturbance | K38: 3 | L38: Tamped/Lined with slues/lifts up to 25mm
C39: 4 | D39: Tamped/lined with slues/lifts > 25mm | K39: 4 | L39: Tamped/Lined with slues/lifts > 25mm
C40: 5 | D40: Mechanised stoneblown | K40: 5 | L40: Mechanised stoneblown
C41: 6 | D41: Tamped or stoneblown S&C | K41: 6 | L41: Manual correction to top and line (MSP, Lift & pack, Kango, orbital tamper, hand-held stoneblown etc.)
C42: 7 | D42: Manual correction to top and line (MSP, Lift & pack, Kango, orbital tamper, hand-held stoneblown etc.) Less than 8 beds | K42: 7 | L42: Ballast disturbance beyond sleeper end only with fully consolidated ballast, ballast profile fully restored
C43: 8 | D43: Manual correction to top and line (MSP, Lift & pack, Kango, orbital tamper, hand-held stoneblown etc.) 8 beds or more | K43: 8 | L43: Ballast generally full between sleepers and on shoulders, but not consolidated (less than 8 beds)
C44: 9 | D44: Ballast disturbance beyond sleeper end only (up to 3 beds) with fully consolidated ballast under the sleepers, ballast profile fully restored | K44: 9 | L44: Ballast generally full between sleepers and on shoulders, but not consolidated (8 beds or more)
C45: 10 | D45: Ballast disturbance beyond sleeper end only (more than 3 beds) with fully consolidated ballast under the sleepers, ballast profile fully restored | J45: Deficiency | K45: 10 | L45: Severe shortage of ballast between sleepers, extending 8 beds or more
C46: 11 | D46: Ballast generally full between sleepers and on shoulders, but not consolidated (less than 8 beds) | K46: 11 | L46: Severe shortage of ballast at sleeper ends, extending 3 beds or more.
C47: 12 | D47: Ballast generally full between sleepers and on shoulders, but not consolidated (8 beds or more) | K47: 12 | L47: Severe shortage of ballast between sleepers and at sleeper ends, extending 8 beds or more
B48: Deficiency | C48: 13 | D48: No ballast shoulder: level with sleeper top (no other disturbance or deficiency) | K48: 13 | L48: 3 or more consecutive sleepers voided at 15mm or more or
C49: 14 | D49: Severe shortage of ballast between sleepers, extending 8 or more consecutive beds | L49: 3 or more consecutive slurried beds, where ballast is not compacted against the sleeper sides/ends
...

Sheet DATA
B3: C. GRANT | D3: C. GRANT | E3: J. SESTER | G3: N/A | H3: a | J3: PL TAMPER | T3: 5
B4: J. CANNING | D4: J. CANNING | E4: J. McGUIRE | G4: YES | J4: S+C TAMPER | T4: 10
B5: L. PEARCE | D5: L. PEARCE | E5: D. BAKER | G5: NO | J5: TANDEM TAMP | T5: 15
B6: S. HANSON | D6: S. HANSON | J6: STONEBLOWER | O6: TGS | T6: 20
B7: L. WELLS | D7: L.WELLS | J7: MULTI PURPOSE STONEBLOWER | O7: STO | T7: 25
B8: D. RUSSELL | D8: D. RUSSELL | J8: REGULATOR | O8: TEAM LEADER | T8: 30
B9: N. BEAUMONT | D9: N. BEAUMONT | J9: N/A | O9: WORKS DELIVERY SUPERVISOR | T9: 35
B10: N. McCABE | D10: N. McCABE | T10: 40
B11: G. HIRST | D11: G. HIRST | T11: 45
H12: CHOOSE TRACK SECTION MANAGER | T12: 50
H13: DONCASTER EAST TRACK SECTION MANAGER | T13: 55
H14: DONCASTER WEST TRACK SECTION MANAGER | T14: 60
H15: GRANTHAM TRACK SECTION MANAGER | T15: 65
T16: 70
T17: 75
T18: 80
T19: 85
T20: 90
T21: 95
T22: 100
T23: 105
T24: 110
T25: 115
T26: 120
T27: 125
... T32: 150

Sheet Sheet1
H4: YES
H5: NO
H6: N/A
